Workbook

Sheet 摘要
A1: ACELON Minga Guazú 新廠 — 巴拉圭總建造成本估算（AACE Class 3，±15–25%）
A2: 估算日期 2026‑09‑16 · 幣別 USD · 匯率 ₲5,934.88/USD（BCP）· 範圍：三棟廠房土建、外殼、裝修、建築機電、公用設備土建整合、基地工程；不含製程設備、製程管線與製程空調、土地租金
A4: 項次 | B4: 項目 | C4: 金額 (USD) | D4: USD/m² | E4: 金額 (₲ 百萬) | F4: 說明
A5: A | B5: 原絲廠房 Nave N 直接成本（RC 4 層 + 1.5F + 地下風道，9,040 m²） | C5: =原絲廠房!$F$67 -> 4262063.5 | D5: =C5/9040 -> 471.4672 | E5: =C5*假設與單價!$C$5/1000000 -> 25294.835 | F5: 詳「原絲廠房」表；數量由 S&W IFC 量得
A6: B | B6: 假撚廠房 DTY 直接成本（鋼構 2 層，4,700 m²） | C6: =假撚廠房!$F$52 -> 2573356.3 | D6: =C6/4700 -> 547.52261 | E6: =C6*假設與單價!$C$5/1000000 -> 15272.561 | F6: 詳「假撚廠房」表
A7: C | B7: 公用廠房與公用設備土建整合直接成本（1,600 m²） | C7: =公用廠房!$F$41 -> 1857432 | D7: =C7/1600 -> 1160.895 | E7: =C7*假設與單價!$C$5/1000000 -> 11023.636 | F7: 詳「公用廠房」表
A8: D | B8: 基地工程直接成本（158 × 106 m） | C8: =基地工程!$F$29 -> 860216.4 | E8: =C8*假設與單價!$C$5/1000000 -> 5105.2811 | F8: 詳「基地工程」表
B9: 直接成本小計 (A+B+C+D) | C9: =SUM(C5:C8) -> 9553068.2 | D9: =C9/(9040+4700+1600) -> 622.75542 | E9: =C9*假設與單價!$C$5/1000000 -> 56696.313 | F9: USD/m² 以三棟 GFA 15,340 m² 計
A11: E | B11: 承包商管理費與利潤 | C11: =C9*假設與單價!$C$42 -> 1337429.5 | E11: =C11*假設與單價!$C$5/1000000 -> 7937.4839 | F11: OHP 14%（CYPE 單價為直接成本）
A12: F | B12: 地質鑽探與土壤試驗 | C12: =假設與單價!$C$47 -> 18000 | E12: =C12*假設與單價!$C$5/1000000 -> 106.82784 | F12: RFI 27
A13: G | B13: 設計費（執行設計＋BIM＋結構＋機電） | C13: =C9*假設與單價!$C$43 -> 429888.07 | E13: =C13*假設與單價!$C$5/1000000 -> 2551.3341 | F13: 4.5%
A14: H | B14: 監造／專案管理 | C14: =C9*假設與單價!$C$44 -> 286592.05 | E14: =C14*假設與單價!$C$5/1000000 -> 1700.8894 | F14: 3%
A15: I | B15: 建照、市府規費、環評、消防審查 | C15: =C9*假設與單價!$C$45 -> 114636.82 | E15: =C15*假設與單價!$C$5/1000000 -> 680.35576 | F15: 1.2%
A16: J | B16: 工程保險（CAR） | C16: =C9*假設與單價!$C$46 -> 76424.545 | E16: =C16*假設與單價!$C$5/1000000 -> 453.57051 | F16: 0.8%
B17: 工程費用（不含預備費與稅） | C17: =C9+SUM(C11:C16) -> 11816039 | E17: =C17*假設與單價!$C$5/1000000 -> 70126.775
A18: K | B18: 工程預備費（設計深度、地質、設備荷重等未定項） | C18: =C17*假設與單價!$C$48 -> 1181603.9 | E18: =C18*假設與單價!$C$5/1000000 -> 7012.6775 | F18: 10%
B19: 總建造成本（未稅） | C19: =C17+C18 -> 12997643 | D19: =C19/(9040+4700+1600) -> 847.30398 | E19: =C19*假設與單價!$C$5/1000000 -> 77139.452
A20: L | B20: IVA 10%（營建材料與勞務；進口設備若適用 Maquila／Ley 60/90 可免） | C20: =C19*假設與單價!$C$49 -> 1299764.3 | E20: =C20*假設與單價!$C$5/1000000 -> 7713.9452
B21: 總建造成本（含 IVA） | C21: =C19+C20 -> 14297407 | D21: =C21/(9040+4700+1600) -> 932.03438 | E21: =C21*假設與單價!$C$5/1000000 -> 84853.397
B23: 估算區間（Class 3：−15% / +25%） | C23: =C19*0.85 -> 11047997 | D23: 低 | E23: =C19*1.25 -> 16247054 | F23: 高（未稅）
B25: 與 ACELON 概算表（巴拉圭投資金額概算‑廠房，WhatsApp 2026‑09‑10）比較
B26: 項目 | C26: ACELON 概算 (NT$) | D26: ACELON 換算 USD | E26: 本估算 USD（含 OHP、未稅） | F26: 差異 %
B27: 原絲廠房 RC 工程（含消防、水電、電梯、地磅、雜項、設計） | C27: 318095600 | D27: =C27/假設與單價!$C$6 -> 9940487.5 | E27: =原絲廠房!$F$67*(1+假設與單價!$C$42)+假設與單價!$C$37 -> 4920752.4 | F27: =E27/D27-1 -> -0.50497877
B28: 假撚廠房鋼構工程（含消防、水電、雜項、設計） | C28: 85601000 | D28: =C28/假設與單價!$C$6 -> 2675031.2 | E28: =假撚廠房!$F$52*(1+假設與單價!$C$42) -> 2933626.2 | F28: =E28/D28-1 -> 0.096669868
B29: 公用廠房 RC 工程（含消防、水電、設計） | C29: 55424000 | D29: =C29/假設與單價!$C$6 -> 1732000 | E29: =公用廠房!$F$41*(1+假設與單價!$C$42) -> 2117472.5 | F29: =E29/D29-1 -> 0.22255918
B30: 合計 | C30: =SUM(C27:C29) -> 459120600 | D30: =SUM(D27:D29) -> 14347519 | E30: =SUM(E27:E29) -> 9971851 | F30: =E30/D30-1 -> -0.30497731
B31: 註：ACELON 概算未含基地工程、公用設備、預備費與稅；本估算之基地工程與公用設備另列，故上表僅比較三棟建築。ACELON 概算幣別依單價量級判定為新台幣（假設 32 NT$/USD）。
B33: 圖例：藍字＝輸入值（可修改）；黑字＝公式；綠字＝連結其他工作表；黃底＝關鍵假設與總額。修改「假設與單價」表即全表重算。

Sheet 假設與單價
A1: ACELON Minga Guazú 新廠 — 建造成本估算：假設與單價
A2: 藍字＝可修改的輸入值；黑字＝公式。所有金額以 USD 計，匯率與單價來源見備註欄。估算基準日 2026‑09‑16。
A4: 代號 | B4: 項目 | C4: 數值 | D4: 單位 | E4: 來源 / 說明
A5: FX | B5: 匯率 USD/PYG（BCP 2026‑09‑15 參考匯率） | C5: 5934.88 | D5: ₲/USD | E5: BCP Cotización referencial fluctuante interbancario, 15‑09‑2026: https://www.bcp.gov.py/webapps/web/cotizacion/referencial-fluctuante-interbancario
A6: FXNT | B6: 匯率 NTD/USD（供與 ACELON 概算比較） | C6: 32 | D6: NT$/USD | E6: 假設值；ACELON 概算表未註明幣別，依單價量級判定為新台幣（RC 廠房 31,600/m²）
A7: ESC | B7: CYPE 2024 基準單價至 2026 之物價調整係數 | C7: 1.1 | D7: 倍 | E7: CAPACO：2025 年 3 月磚 +8.2%、水泥 +6.3%、泥作工資 +3.4%（Última Hora 2025‑05‑06）；兩年累計取 +10%
A8: CONC | B8: 混凝土 fck 250 泵送到位（含振搗養護） | C8: =900000*1.12*假設與單價!$C$7/假設與單價!$C$5 -> 186.8277 | D8: USD/m³ | E8: costeo.com.py：Hormigón Fck=250 bombeado ₲900,000/m³；加澆置人工與損耗 12%
A9: REB | B9: 鋼筋 AP500 供料＋加工＋綁紮 | C9: =(7390+1400)*假設與單價!$C$7/假設與單價!$C$5 -> 1.6291821 | D9: USD/kg | E9: costeo.com.py：varilla conformada ₲7,390/kg；加工綁紮人工＋鐵線約 ₲1,400/kg
A10: FWC | B10: 模板—柱樑（鋼模／木模，含支撐） | C10: 26 | D10: USD/m² | E10: CYPE Paraguay EHS010（鋼板模 50 次攤提）₲296,843/m² 為含大量攤提之高值；依當地習慣木模＋鋼管支撐取 USD 26/m²
A11: FWS | B11: 模板—樓板（含 3.7–4 m 支撐） | C11: 22 | D11: USD/m² | E11: CYPE Paraguay 樓板 24 cm 單價 ₲583,257/m² 中材料含模板 25 次攤提；取 USD 22/m²
A12: EXC | B12: 土方開挖與回填（機械） | C12: 9 | D12: USD/m³ | E12: 當地行情估計（挖土機＋運棄 10 km 內）
A13: LEAN | B13: 墊層混凝土 fck 150（10 cm） | C13: 95 | D13: USD/m³ | E13: costeo/CYPE HM‑15 ≈ ₲560,000/m³
A14: SOG | B14: 工業地坪 20 cm 纖維混凝土＋硬化劑（含整平、切縫） | C14: =335751*假設與單價!$C$7/假設與單價!$C$5 -> 62.22975 | D14: USD/m² | E14: CYPE Paraguay RSI007：₲335,751/m² × ESC
A15: RCW | B15: RC 外牆 20 cm（含雙面模板、鋼筋 80 kg/m³） | C15: =0.2*假設與單價!$C$8+16*假設與單價!$C$9+2*假設與單價!$C$10 -> 115.43245 | D15: USD/m² | E15: 由 CONC/REB/FWC 組成：0.2 m³ + 16 kg + 2 m² 模板
A16: BRK | B16: 砌磚隔間 15 cm（空心磚） | C16: =106527*1.9*假設與單價!$C$7/假設與單價!$C$5 -> 37.514058 | D16: USD/m² | E16: CYPE Paraguay FFQ010（7 cm 雙孔磚）₲106,527/m²；15 cm 牆取 1.9 倍 × ESC
A17: PLA | B17: 粉刷＋油漆（每面） | C17: 11 | D17: USD/m² | E17: 當地行情：粉刷 ₲35,000 + 乳膠漆 ₲28,000 /m²
A18: ZINC4 | B18: 屋頂 Zincalum 4合1 隔熱三明治板 100 mm（含固定件、收邊） | C18: =439960*假設與單價!$C$7/假設與單價!$C$5 -> 81.544361 | D18: USD/m² | E18: CYPE Paraguay QUM020：₲439,960/m² × ESC
A19: ZINC2 | B19: 外牆 Zincalum 2合1 板（4F 側牆／DTY 外牆，含次結構） | C19: 42 | D19: USD/m² | E19: 三明治板約 6 成價位；含 C 型鋼牆桁
A20: STL | B20: 鋼結構 A36 熱軋型鋼—製作、防鏽漆、安裝 | C20: =383251/32.8*假設與單價!$C$7*1.05/假設與單價!$C$5 -> 2.2739426 | D20: USD/kg | E20: CYPE Paraguay EAM010：門式鋼架 ₲383,251/m² ÷ 32.8 kg/m² = ₲11,684/kg × ESC；重型 29 m 跨另加 5%
A21: STLKG | B21: DTY 鋼架用鋼量（29 m 雙跨、簷高 11 m、含桁條） | C21: 55 | D21: kg/m² | E21: CYPE 基準 32.8 kg/m² 為 <10 m 跨、5 m 高；58 m 寬雙跨廠房經驗值 50–60 kg/m²
A22: MEZZ | B22: 夾層樓板（鋼承板＋12 cm RC） | C22: 95 | D22: USD/m² | E22: 含鋼承板、鋼筋網、混凝土；不含主梁（計入 STL）
A23: PAV | B23: 廠區道路／停車場：混凝土鋪面 18 cm | C23: 48 | D23: USD/m² | E23: CYPE UXC020 戶外連續混凝土鋪面約 ₲250,000/m²；含級配底層
A24: FEN | B24: 四周圍牆 2.4 m（RC 柱＋磚牆，P0A30170） | C24: 135 | D24: USD/m | E24: RC 柱 @3 m + 15 cm 磚牆 + 粉刷 + 基礎
A25: ELEV | B25: 貨梯 3,000 kg、5 站（進口＋安裝） | C25: 95000 | D25: USD/台 | E25: 南美市場進口貨梯 3 t 5 停行情 USD 80–110k
A26: RDOOR | B26: 鐵捲門＋小門（4.5 × 4.5 m） | C26: 4200 | D26: USD/樘 | E26: 當地行情
A27: FDOOR | B27: 快速捲門 50–100 cm/s（進口，含互鎖控制） | C27: 9500 | D27: USD/樘 | E27: 9/4 回覆要求；進口 PVC 快速門行情
A28: WC | B28: 廁所（樓梯平台型，每處含衛生設備、給排水、貼磚） | C28: 6500 | D28: USD/處 | E28: 當地行情
A29: ELEC | B29: 建築用電（低壓配電盤、幹線、插座；不含製程配電） | C29: 55 | D29: USD/m² | E29: 工業廠房行情；ACELON 概算「水電」NT$750/m² ≈ USD 23/m² 明顯偏低
A30: LIGHT | B30: 照明（LED 高天井燈、辦公照明、緊急照明） | C30: 14 | D30: USD/m² | E30: 當地行情
A31: TEL | B31: 電信／弱電／監視及網路 | C31: 8 | D31: USD/m² | E31: 9/4 回覆要求「五大管線」含電信
A32: PLB | B32: 給排水（建築用；不含製程水） | C32: 16 | D32: USD/m² | E32: 當地行情
... A49: IVA | B49: IVA 加值稅（材料與勞務） | C49: 0.1 | D49: % | E49: 巴拉圭 IVA 10%；若採 Maquila／Ley 60/90 可申請進口設備免稅，營建勞務仍課 10%

Sheet 數量計算-原絲廠房
A1: 原絲廠房 Nave N — 工程數量計算（來源：Salum & Wenz IFC 2026‑07‑31 幾何體積 ＋ 9/4 回覆之外殼規格）
A2: 混凝土體積直接由 IFC 實體量得；鋼筋量以含鋼率估計；模板以構件表面積估計。藍字為假設係數。
A4: 樓層 | B4: 構件 | C4: IFC 數量 | D4: 混凝土 m³ | E4: 表面積 m² | F4: 含鋼率 kg/m³ | G4: 鋼筋 kg | H4: 模板係數 | I4: 模板 m² | J4: 說明
A5: Fundacion | B5: 柱 | C5: 30 | D5: 42.1 | E5: 302 | F5: 150 | G5: =D5*F5 -> 6315 | H5: 0.95 | I5: =IF(D5>0,E5*H5,0) -> 286.9 | J5: IFC 實體體積
A6: Fundacion | B6: 樑 | C6: 14 | D6: 30.9 | E6: 471 | F6: 130 | G6: =D6*F6 -> 4017 | H6: 0.75 | I6: =IF(D6>0,E6*H6,0) -> 353.25 | J6: IFC 實體體積
A7: Fundacion | B7: 樓板 | C7: 30 | D7: 34.6 | E7: 202 | F7: 100 | G7: =D7*F7 -> 3460 | H7: 0.5 | I7: =IF(D7>0,E7*H7,0) -> 101 | J7: IFC 實體體積
A8: GL+200(1FL) | B8: 柱 | C8: 30 | D8: 36.6 | E8: 276 | F8: 150 | G8: =D8*F8 -> 5490 | H8: 0.95 | I8: =IF(D8>0,E8*H8,0) -> 262.2 | J8: IFC 實體體積
A9: GL+200(1FL) | B9: 樑 | C9: 53 | D9: 168.6 | E9: 1474 | F9: 130 | G9: =D9*F9 -> 21918 | H9: 0.75 | I9: =IF(D9>0,E9*H9,0) -> 1105.5 | J9: IFC 實體體積
A10: GL+200(1FL) | B10: 樓板 | C10: 3 | D10: 328.7 | E10: 3366 | F10: 100 | G10: =D10*F10 -> 32870 | H10: 0.5 | I10: =IF(D10>0,E10*H10,0) -> 1683 | J10: IFC 實體體積（部分構件以外框估算）
A11: GL+200(1FL) | B11: RC 牆（樓梯間） | C11: 8 | D11: 18.6 | E11: 268 | F11: 80 | G11: =D11*F11 -> 1488 | H11: 0.9 | I11: =IF(D11>0,E11*H11,0) -> 241.2 | J11: IFC 實體體積
A12: GL+200(1FL) | B12: 樓梯 | C12: 4 | D12: 21.7 | E12: 92 | F12: 110 | G12: =D12*F12 -> 2387 | H12: 0.6 | I12: =IF(D12>0,E12*H12,0) -> 55.2 | J12: IFC 實體體積（部分構件以外框估算）
A13: GL+3700(1.5FL) | B13: 柱 | C13: 29 | D13: 34.7 | E13: 257 | F13: 150 | G13: =D13*F13 -> 5205 | H13: 0.95 | I13: =IF(D13>0,E13*H13,0) -> 244.15 | J13: IFC 實體體積
A14: GL+3700(1.5FL) | B14: 樑 | C14: 32 | D14: 135.4 | E14: 1135 | F14: 130 | G14: =D14*F14 -> 17602 | H14: 0.75 | I14: =IF(D14>0,E14*H14,0) -> 851.25 | J14: IFC 實體體積
A15: GL+3700(1.5FL) | B15: 樓板 | C15: 3 | D15: 178.4 | E15: 1843 | F15: 100 | G15: =D15*F15 -> 17840 | H15: 0.5 | I15: =IF(D15>0,E15*H15,0) -> 921.5 | J15: IFC 實體體積（部分構件以外框估算）
A16: GL+3700(1.5FL) | B16: RC 牆（樓梯間） | C16: 8 | D16: 17.6 | E16: 254 | F16: 80 | G16: =D16*F16 -> 1408 | H16: 0.9 | I16: =IF(D16>0,E16*H16,0) -> 228.6 | J16: IFC 實體體積
... A34: GL+23200 | B34: 樓板 | C34: 2 | D34: 0 | E34: 2302 | F34: 100 | G34: =D34*F34 -> 0 | H34: 0.5 | I34: =IF(D34>0,E34*H34,0) -> 0 | J34: 屋頂層板：IFC 中為薄板（Zincalum 屋面示意），不計混凝土
A35: IFC 結構合計 | D35: =SUM(D5:D34) -> 2711.9 | G35: =SUM(G5:G34) -> 309447 | I35: =SUM(I5:I34) -> 16095.45
A37: 補充數量（IFC 未含，依圖說與 9/4 回覆）
A38: 代號 | B38: 項目 | C38: 數值 | D38: 單位 | E38: 計算式 / 依據
A39: FOOT | B39: 基礎版擴大（IFC 基礎為示意，深度待地質鑽探）：30 座 × 3.5×3.5×0.9 m | C39: =30*3.5*3.5*0.9 -> 330.75 | D39: m³ | E39: RFI 27：基礎深度由建築師依鑽探定；4 層 RC 廠房、樓板荷重 1,000 kg/m² 與 9,500 kg/區估算
A40: EXCV | B40: 基礎與地下風道開挖（含工作面 1 m） | C40: =30*4.5*4.5*2+560*3 -> 2895 | D40: m³ | E40: 基礎坑 30 座 + 風道溝 560 m² × 3 m 深
A41: DUCT | B41: 地下風道 RC（9/4 回覆：RC 製造，兩道連通）：牆＋底板＋頂板 | C41: =(769+571)*0.25 -> 335 | D41: m³ | E41: IFC 風道實體表面積 769 + 571 m² × 厚 25 cm
A42: DUCTF | B42: 地下風道模板 | C42: =(769+571)*1.6 -> 2144 | D42: m² | E42: 內外側模板
A43: SOGA | B43: 1F 工業地坪面積 | C43: =23.2*73.4 -> 1702.88 | D43: m² | E43: 建築外框（IFC 1F 樓板為地坪，混凝土已計於結構；此處計硬化面層與切縫）
A44: PERIM | B44: 建築周長 | C44: =2*(23.2+73.4) -> 193.2 | D44: m | E44: P0A30011 外框 23.2 × 73.4 m
A45: RCWA | B45: 1–3F RC 外牆面積（9/4 回覆：不可用空心磚） | C45: =C44*15.2*0.88 -> 2584.2432 | D45: m² | E45: 周長 × 15.2 m（GL 至 4F 樓板）× 0.88（扣門窗開口）
A46: ZWA | B46: 4F 側牆 Zincalum 2合1 板面積 | C46: =C44*6 -> 1159.2 | D46: m² | E46: 周長 × 6.0 m（15.2 至簷口 21.2）
A47: ROOF | B47: 屋頂 Zincalum 4合1 板面積（含坡度） | C47: =23.7*75.1*1.03 -> 1833.2661 | D47: m² | E47: 投影面積 × 1.03
A48: BRKA | B48: 砌磚隔間面積（1–4F 所有隔間含樓梯間） | C48: =1350 -> 1350 | D48: m² | E48: IFC 樓梯間牆 530 m² + 4F 房間（紡口清潔／燃燒室／組裝檢驗／水處理）+ 3F 處理油攪拌室 + 1.5F 控制室、空調室 估 820 m²
A49: GFA | B49: 總樓地板面積（ACELON 概算基準） | C49: =9040 -> 9040 | D49: m² | E49: ACELON 概算表：23M×73M×4 樓（含地下室及一樓半）9,040 m²
A50: OPEN | B50: 設備放孔補強（角鐵 SS400）＋防水墩：1000×1000 放孔 | C50: =60 -> 60 | D50: 孔 | E50: 1.5F / 2F / 3F 各 20 孔（P0A30041/51/61）

Sheet 原絲廠房
A1: 原絲廠房 Nave N（23.7 × 75.1 m，RC 4 層 + 1.5F + 地下風道；GFA 9,040 m²）— 直接成本明細
A2: 數量來自 IFC 與圖說；單價連結「假設與單價」表（綠字）。不含製程設備、製程管線、製程空調。
A4: 項次 | B4: 工程項目 | C4: 數量 | D4: 單位 | E4: 單價 (USD) | F4: 金額 (USD) | G4: 數量依據 / 說明
A5: 1 | B5: 土方與基礎
A6: 1.1 | B6: 基礎與地下風道開挖、回填、運棄 | C6: ='數量計算-原絲廠房'!$C$40 -> 2895 | D6: m³ | E6: =假設與單價!$C$12 -> 9 | F6: =C6*E6 -> 26055 | G6: 數量計算表 EXCV
A7: 1.2 | B7: 墊層混凝土 fck150 10 cm（基礎版與風道底） | C7: =(30*4.5*4.5+560)*0.1 -> 116.75 | D7: m³ | E7: =假設與單價!$C$13 -> 95 | F7: =C7*E7 -> 11091.25 | G7: 基礎坑面積 + 風道底面積 × 0.1 m
A8: 1.3 | B8: 基礎版擴大 RC 混凝土 | C8: ='數量計算-原絲廠房'!$C$39 -> 330.75 | D8: m³ | E8: =假設與單價!$C$8 -> 186.8277 | F8: =C8*E8 -> 61793.263 | G8: 數量計算表 FOOT（IFC 基礎 34.6 m³ 為示意，改採估算值）
A9: 1.4 | B9: 基礎版鋼筋（60 kg/m³） | C9: ='數量計算-原絲廠房'!$C$39*60 -> 19845 | D9: kg | E9: =假設與單價!$C$9 -> 1.6291821 | F9: =C9*E9 -> 32331.118 | G9: 含鋼率 60 kg/m³（CYPE 基礎 50 kg/m³ + 重載）
A10: 1.5 | B10: 基礎版模板 | C10: =30*4*3.5*0.9 -> 378 | D10: m² | E10: =假設與單價!$C$10 -> 26 | F10: =C10*E10 -> 9828 | G10: 側模
A11: 1.6 | B11: 地樑與基礎柱 RC（IFC Fundación 樑 30.9 + 柱 42.1 m³） | C11: =30.9+42.1 -> 73 | D11: m³ | E11: =假設與單價!$C$8 -> 186.8277 | F11: =C11*E11 -> 13638.422 | G11: IFC Fundación 層
A12: 1.7 | B12: 地樑與基礎柱鋼筋（140 kg/m³） | C12: =(30.9+42.1)*140 -> 10220 | D12: kg | E12: =假設與單價!$C$9 -> 1.6291821 | F12: =C12*E12 -> 16650.241
A13: 1.8 | B13: 地樑與基礎柱模板 | C13: =471*0.75+302*0.95 -> 640.15 | D13: m² | E13: =假設與單價!$C$10 -> 26 | F13: =C13*E13 -> 16643.9 | G13: IFC 表面積 × 係數
A14: 1.9 | B14: 地下風道 RC 混凝土（兩道連通，RC 非鐵板） | C14: ='數量計算-原絲廠房'!$C$41 -> 335 | D14: m³ | E14: =假設與單價!$C$8 -> 186.8277 | F14: =C14*E14 -> 62587.281 | G14: 9/4 回覆第 1 點；數量計算表 DUCT
A15: 1.10 | B15: 地下風道鋼筋（90 kg/m³） | C15: ='數量計算-原絲廠房'!$C$41*90 -> 30150 | D15: kg | E15: =假設與單價!$C$9 -> 1.6291821 | F15: =C15*E15 -> 49119.839
A16: 1.11 | B16: 地下風道模板 | C16: ='數量計算-原絲廠房'!$C$42 -> 2144 | D16: m² | E16: =假設與單價!$C$10 -> 26 | F16: =C16*E16 -> 55744
A17: 1.12 | B17: 地下風道防水與內面粉光 | C17: =769+571 -> 1340 | D17: m² | E17: 9 | F17: =C17*E17 -> 12060 | G17: 水泥基防水塗料 + 粉光（送冷風用）
B18: 小計 1. 土方與基礎 | F18: =SUM(F6:F17) -> 367542.31
A20: 2 | B20: 上部 RC 結構（1F–4F，含 1.5F 技術層）
A21: 2.1 | B21: 柱、樑、樓板、樓梯、RC 牆混凝土 fck250（IFC 實體體積） | C21: ='數量計算-原絲廠房'!$D$35-30.9-42.1-34.6 -> 2604.3 | D21: m³ | E21: =假設與單價!$C$8 -> 186.8277 | F21: =C21*E21 -> 486555.39 | G21: 數量計算表合計扣除 Fundación 層（已計於基礎）
A22: 2.2 | B22: 鋼筋（依構件含鋼率 100–150 kg/m³） | C22: ='數量計算-原絲廠房'!$G$35-(30.9*130+42.1*150+34.6*100) -> 295655 | D22: kg | E22: =假設與單價!$C$9 -> 1.6291821 | F22: =C22*E22 -> 481675.82 | G22: 數量計算表鋼筋合計扣除基礎層
A23: 2.3 | B23: 柱樑模板 | C23: =SUMPRODUCT(('數量計算-原絲廠房'!B5:B34="柱")+('數量計算-原絲廠房'!B5:B34="樑"),'數量計算-原絲廠房'!I5:I34)-471*0.75-302*0.95 -> 6961.4 | D23: m² | E23: =假設與單價!$C$10 -> 26 | F23: =C23*E23 -> 180996.4 | G23: 數量計算表柱樑模板扣除基礎層
A24: 2.4 | B24: 樓板與樓梯模板（含 3.5–4 m 支撐） | C24: =SUMPRODUCT(('數量計算-原絲廠房'!B5:B34="樓板")+('數量計算-原絲廠房'!B5:B34="樓梯")+('數量計算-原絲廠房'!B5:B34="RC 牆（樓梯間）"),'數量計算-原絲廠房'!I5:I34)-202*0.5 -> 8392.9 | D24: m² | E24: =假設與單價!$C$11 -> 22 | F24: =C24*E24 -> 184643.8 | G24: 扣除基礎版
A25: 2.5 | B25: 放孔補強角鐵 SS400 ＋ 防水墩（1000×1000，60 孔） | C25: ='數量計算-原絲廠房'!$C$50 -> 60 | D25: 孔 | E25: 260 | F25: =C25*E25 -> 15600 | G25: 9/4 回覆：設備放孔角鐵補強、空調放孔防水墩
A26: 2.6 | B26: 3F 20 mm 鋼底板 3.8 × 8 m（RFI 23，若為獨立設備基礎） | C26: =3.8*8*0.02*7850 -> 4772.8 | D26: kg | E26: 2.6 | F26: =C26*E26 -> 12409.28 | G26: 鋼板供料＋安裝 USD 2.6/kg；是否需要待 ACELON 確認
A27: 2.7 | B27: 4F 天車軌道（Skycar，含軌道樑，噸位待定 RFI 24） | C27: =2*73 -> 146 | D27: m | E27: 320 | F27: =C27*E27 -> 46720 | G27: 軌道 2 條 × 73 m；以 3 t 級估
A28: 2.8 | B28: 1F 工業地坪硬化面層與切縫（IFC 1F 板混凝土已計） | C28: ='數量計算-原絲廠房'!$C$43 -> 1702.88 | D28: m² | E28: =假設與單價!$C$14*0.35 -> 21.780413 | F28: =C28*E28 -> 37089.429 | G28: 僅計硬化劑、機械抹光、切縫（混凝土在結構項）
B29: 小計 2. 上部 RC 結構（1F–4F，含 1.5F 技術層） | F29: =SUM(F21:F28) -> 1445690.1
A31: 3 | B31: 外殼（依 9/4 回覆：1–3F RC 外牆、4F Zincalum、屋頂 4合1）
A32: 3.1 | B32: 1–3F RC 外牆 20 cm（含模板、鋼筋） | C32: ='數量計算-原絲廠房'!$C$45 -> 2584.2432 | D32: m² | E32: =假設與單價!$C$15 -> 115.43245 | F32: =C32*E32 -> 298305.53 | G32: 數量計算表 RCWA；9/4 回覆第 5 點
A33: 3.2 | B33: RC 外牆外側粉刷＋防水漆 | C33: ='數量計算-原絲廠房'!$C$45 -> 2584.2432 | D33: m² | E33: 13 | F33: =C33*E33 -> 33595.162 | G33: 彈性防水漆
A34: 3.3 | B34: RC 外牆內側粉刷＋油漆 | C34: ='數量計算-原絲廠房'!$C$45 -> 2584.2432 | D34: m² | E34: =假設與單價!$C$17 -> 11 | F34: =C34*E34 -> 28426.675
A35: 3.4 | B35: 4F 側牆 Zincalum 2合1 板（含 C 型鋼牆桁） | C35: ='數量計算-原絲廠房'!$C$46 -> 1159.2 | D35: m² | E35: =假設與單價!$C$19 -> 42 | F35: =C35*E35 -> 48686.4 | G35: 數量計算表 ZWA
A36: 3.5 | B36: 屋頂 Zincalum 4合1 三明治板（含固定件、脊蓋） | C36: ='數量計算-原絲廠房'!$C$47 -> 1833.2661 | D36: m² | E36: =假設與單價!$C$18 -> 81.544361 | F36: =C36*E36 -> 149492.51 | G36: 數量計算表 ROOF；鎂板成分待 S&W 第 2 階段確認（RFI 19）
A37: 3.6 | B37: 屋頂鋼桁條與天溝（時雨量 120 mm/h）、落水管 | C37: ='數量計算-原絲廠房'!$C$47 -> 1833.2661 | D37: m² | E37: 18 | F37: =C37*E37 -> 32998.79 | G37: 桁條 8 kg/m² × STL + 天溝
A38: 3.7 | B38: 鐵捲門＋小門 | C38: =6 -> 6 | D38: 樘 | E38: =假設與單價!$C$26 -> 4200 | F38: =C38*E38 -> 25200 | G38: P0A30031：西側 3 樘、東側 2 樘、北側 1 樘
A39: 3.8 | B39: 快速捲門（互鎖控制） | C39: =4 -> 4 | D39: 樘 | E39: =假設與單價!$C$27 -> 9500 | F39: =C39*E39 -> 38000 | G39: 9/4 回覆第 9 點：空調廠房用快速捲門 50–100 cm/s
A40: 3.9 | B40: 外牆門窗（鋁窗、鋼門） | C40: =1 -> 1 | D40: 式 | E40: 38000 | F40: =C40*E40 -> 38000 | G40: 1F 辦公／控制室窗、逃生門、樓梯間門
B41: 小計 3. 外殼（依 9/4 回覆：1–3F RC 外牆、4F Zincalum、屋頂 4合1） | F41: =SUM(F32:F40) -> 692705.07
A43: 4 | B43: 內部裝修
A44: 4.1 | B44: 砌磚隔間 15 cm（含樓梯間；1–4F） | C44: ='數量計算-原絲廠房'!$C$48 -> 1350 | D44: m² | E44: =假設與單價!$C$16 -> 37.514058 | F44: =C44*E44 -> 50643.978 | G44: 9/4 回覆第 6 點；數量計算表 BRKA
...

Sheet 假撚廠房
A1: 假撚廠房 DTY（58 × 73.4 m，鋼構 2 層，GFA 4,700 m²）— 直接成本明細
A2: 尚無 Salum & Wenz 圖說；數量依總平面圖 P0A30011 與概算表規格推算。
A4: 項次 | B4: 工程項目 | C4: 數量 | D4: 單位 | E4: 單價 (USD) | F4: 金額 (USD) | G4: 數量依據 / 說明
A5: 1 | B5: 土方與基礎
A6: 1.1 | B6: 柱基礎開挖、回填 | C6: =72*3.5*3.5*1.8 -> 1587.6 | D6: m³ | E6: =假設與單價!$C$12 -> 9 | F6: =C6*E6 -> 14288.4 | G6: 8 × 9 柱位 = 72 座
A7: 1.2 | B7: 墊層混凝土 | C7: =72*3.5*3.5*0.1 -> 88.2 | D7: m³ | E7: =假設與單價!$C$13 -> 95 | F7: =C7*E7 -> 8379
A8: 1.3 | B8: 柱基礎 RC（72 座 × 3.0×3.0×0.8 + 短柱） | C8: =72*(3*3*0.8+0.5*0.5*1.5) -> 545.4 | D8: m³ | E8: =假設與單價!$C$8 -> 186.8277 | F8: =C8*E8 -> 101895.83 | G8: 58 m 寬雙跨鋼構、簷高 11 m
A9: 1.4 | B9: 基礎鋼筋（60 kg/m³） | C9: =72*(3*3*0.8+0.5*0.5*1.5)*60 -> 32724 | D9: kg | E9: =假設與單價!$C$9 -> 1.6291821 | F9: =C9*E9 -> 53313.354
A10: 1.5 | B10: 基礎模板 | C10: =72*(4*3*0.8+4*0.5*1.5) -> 907.2 | D10: m² | E10: =假設與單價!$C$10 -> 26 | F10: =C10*E10 -> 23587.2
A11: 1.6 | B11: 地樑（周邊與夾層下） | C11: =(2*(58+73.4)+58*2)*0.3*0.5 -> 56.82 | D11: m³ | E11: =假設與單價!$C$8 -> 186.8277 | F11: =C11*E11 -> 10615.55 | G11: 周長 + 夾層 2 條
A12: 1.7 | B12: 地樑鋼筋（130 kg/m³） | C12: =(2*(58+73.4)+58*2)*0.3*0.5*130 -> 7386.6 | D12: kg | E12: =假設與單價!$C$9 -> 1.6291821 | F12: =C12*E12 -> 12034.116
A13: 1.8 | B13: 地樑模板 | C13: =(2*(58+73.4)+58*2)*1 -> 378.8 | D13: m² | E13: =假設與單價!$C$10 -> 26 | F13: =C13*E13 -> 9848.8
B14: 小計 1. 土方與基礎 | F14: =SUM(F6:F13) -> 233962.25
A16: 2 | B16: 鋼結構
A17: 2.1 | B17: 主鋼架、桁條、拉條、支撐（A36，製作＋防鏽＋安裝） | C17: =58*73.4*假設與單價!$C$21 -> 234146 | D17: kg | E17: =假設與單價!$C$20 -> 2.2739426 | F17: =C17*E17 -> 532434.56 | G17: 面積 4,257 m² × 用鋼量；假設值 STLKG
A18: 2.2 | B18: 與原絲廠房共牆側預留牛腿（P0A30011 註記） | C18: =9 -> 9 | D18: 座 | E18: 1400 | F18: =C18*E18 -> 12600 | G18: 預留 DTY 廠房樑柱支撐牛腿
A19: 2.3 | B19: 北側夾層鋼樑（58 × 15.4 m，45 kg/m²） | C19: =58*15.4*45 -> 40194 | D19: kg | E19: =假設與單價!$C$20 -> 2.2739426 | F19: =C19*E19 -> 91398.848 | G19: 2F 空調區、備品室、教育訓練、會議室
A20: 2.4 | B20: 夾層樓板（鋼承板 + 12 cm RC） | C20: =58*15.4 -> 893.2 | D20: m² | E20: =假設與單價!$C$22 -> 95 | F20: =C20*E20 -> 84854
A21: 2.5 | B21: 夾層樓梯 2 座（鋼構） | C21: =2 -> 2 | D21: 座 | E21: 9500 | F21: =C21*E21 -> 19000
B22: 小計 2. 鋼結構 | F22: =SUM(F17:F21) -> 740287.41
A24: 3 | B24: 外殼與地坪
A25: 3.1 | B25: 屋頂 Zincalum 4合1 三明治板 | C25: =58*73.4*1.03 -> 4384.916 | D25: m² | E25: =假設與單價!$C$18 -> 81.544361 | F25: =C25*E25 -> 357565.18 | G25: S&W 建議三明治板
A26: 3.2 | B26: 屋頂天溝（時雨量 120 mm/h）、落水管、採光帶 | C26: =58*73.4 -> 4257.2 | D26: m² | E26: 9 | F26: =C26*E26 -> 38314.8
A27: 3.3 | B27: 外牆 Zincalum 2合1 板 + 牆桁（下段 2.4 m 磚牆另計） | C27: =2*(58+73.4)*(11-2.4)*0.92 -> 2079.2736 | D27: m² | E27: =假設與單價!$C$19 -> 42 | F27: =C27*E27 -> 87329.491 | G27: 扣門洞 8%
A28: 3.4 | B28: 外牆下段磚牆 2.4 m（防撞）＋粉刷油漆 | C28: =2*(58+73.4)*2.4 -> 630.72 | D28: m² | E28: =假設與單價!$C$16+2*假設與單價!$C$17 -> 59.514058 | F28: =C28*E28 -> 37536.706
A29: 3.5 | B29: 工業地坪 20 cm 纖維混凝土＋硬化劑 | C29: =58*73.4 -> 4257.2 | D29: m² | E29: =假設與單價!$C$14 -> 62.22975 | F29: =C29*E29 -> 264924.49 | G29: 荷重 1,000 kg/m²
A30: 3.6 | B30: 鐵捲門＋小門（紗車暫存區、倉庫、品檢包裝區） | C30: =6 -> 6 | D30: 樘 | E30: =假設與單價!$C$26 -> 4200 | F30: =C30*E30 -> 25200 | G30: P0A30011
A31: 3.7 | B31: 快速捲門（紗車出入、空調區） | C31: =2 -> 2 | D31: 樘 | E31: =假設與單價!$C$27 -> 9500 | F31: =C31*E31 -> 19000
A32: 3.8 | B32: 門窗（辦公、染判室、會議室） | C32: =1 -> 1 | D32: 式 | E32: 32000 | F32: =C32*E32 -> 32000
B33: 小計 3. 外殼與地坪 | F33: =SUM(F25:F32) -> 861870.67
A35: 4 | B35: 內部裝修
A36: 4.1 | B36: 砌磚隔間 15 cm（1F 保養室、辦公室、染判室、廁所、倉庫辦公室；2F 房間） | C36: =780 -> 780 | D36: m² | E36: =假設與單價!$C$16 -> 37.514058 | F36: =C36*E36 -> 29260.965 | G36: 依模型房間周長 × 3.2 m（1F）/ 3.0 m（2F）
A37: 4.2 | B37: 隔間雙面粉刷＋油漆 | C37: =780*2 -> 1560 | D37: m² | E37: =假設與單價!$C$17 -> 11 | F37: =C37*E37 -> 17160
A38: 4.3 | B38: 辦公／訓練／會議／染判室裝修（天花、地坪、照明強化） | C38: =(11*8.5+8*8.5+11*8.5+8*8.5) -> 323 | D38: m² | E38: 45 | F38: =C38*E38 -> 14535
A39: 4.4 | B39: 女廁／男廁 | C39: =2 -> 2 | D39: 處 | E39: =假設與單價!$C$28 -> 6500 | F39: =C39*E39 -> 13000 | G39: P0A30011 東北角
A40: 4.5 | B40: 品檢包裝區環氧地坪 | C40: =22*15 -> 330 | D40: m² | E40: 16 | F40: =C40*E40 -> 5280
B41: 小計 4. 內部裝修 | F41: =SUM(F36:F40) -> 79235.965
A43: 5 | B43: 建築機電
A44: 5.1 | B44: 電氣—建築用電 | C44: =4700 -> 4700 | D44: m² | E44: =假設與單價!$C$29 -> 55 | F44: =C44*E44 -> 258500 | G44: GFA 4,700 m²（ACELON 概算）
A45: 5.2 | B45: 照明 | C45: =4700 -> 4700 | D45: m² | E45: =假設與單價!$C$30 -> 14 | F45: =C45*E45 -> 65800
...

Sheet 公用廠房
A1: 公用廠房（21 × 38 m，RC 2 層，GFA 1,600 m²）與公用設備 — 直接成本明細
A2: 位置依 P0A30011 西側 20 m 公用帶；設備本體是否納入營建範圍待 RFI 30/32。
A4: 項次 | B4: 工程項目 | C4: 數量 | D4: 單位 | E4: 單價 (USD) | F4: 金額 (USD) | G4: 數量依據 / 說明
A5: 1 | B5: 土方與基礎
A6: 1.1 | B6: 基礎開挖、回填 | C6: =24*2.5*2.5*1.5 -> 225 | D6: m³ | E6: =假設與單價!$C$12 -> 9 | F6: =C6*E6 -> 2025 | G6: 4 × 6 柱位
A7: 1.2 | B7: 柱基礎與地樑 RC | C7: =24*2.5*2.5*0.6+(2*(21+38)+38*3)*0.3*0.5 -> 124.8 | D7: m³ | E7: =假設與單價!$C$8 -> 186.8277 | F7: =C7*E7 -> 23316.097
A8: 1.3 | B8: 基礎鋼筋（80 kg/m³） | C8: =(24*2.5*2.5*0.6+(2*(21+38)+38*3)*0.3*0.5)*80 -> 9984 | D8: kg | E8: =假設與單價!$C$9 -> 1.6291821 | F8: =C8*E8 -> 16265.754
A9: 1.4 | B9: 基礎模板 | C9: =24*4*2.5*0.6+(2*(21+38)+38*3)*1 -> 376 | D9: m² | E9: =假設與單價!$C$10 -> 26 | F9: =C9*E9 -> 9776
B10: 小計 1. 土方與基礎 | F10: =SUM(F6:F9) -> 51382.851
A12: 2 | B12: RC 結構（2 層）
A13: 2.1 | B13: 柱樑板混凝土（2 層 × 798 m² × 0.28 m³/m²） | C13: =2*21*38*0.28 -> 446.88 | D13: m³ | E13: =假設與單價!$C$8 -> 186.8277 | F13: =C13*E13 -> 83489.564 | G13: RC 框架含樓板 0.28 m³/m² 經驗值
A14: 2.2 | B14: 鋼筋（115 kg/m³） | C14: =2*21*38*0.28*115 -> 51391.2 | D14: kg | E14: =假設與單價!$C$9 -> 1.6291821 | F14: =C14*E14 -> 83725.621
A15: 2.3 | B15: 模板 | C15: =2*21*38*2.2 -> 3511.2 | D15: m² | E15: =假設與單價!$C$11 -> 22 | F15: =C15*E15 -> 77246.4 | G15: 2.2 m²/m² 樓地板
A16: 2.4 | B16: 設備基礎（空壓機、冷乾機、冷卻水塔、發電機、變壓器） | C16: =45 -> 45 | D16: m³ | E16: =假設與單價!$C$8*1.6 -> 298.92433 | F16: =C16*E16 -> 13451.595 | G16: 含鋼筋模板及防震
B17: 小計 2. RC 結構（2 層） | F17: =SUM(F13:F16) -> 257913.18
A19: 3 | B19: 外殼與裝修
A20: 3.1 | B20: 外牆磚牆 20 cm + 雙面粉刷油漆 | C20: =2*(21+38)*9*0.85 -> 902.7 | D20: m² | E20: =假設與單價!$C$16*1.15+2*假設與單價!$C$17 -> 65.141166 | F20: =C20*E20 -> 58802.931 | G20: 扣門窗 15%
A21: 3.2 | B21: 屋頂 Zincalum 4合1 板 + 桁條 | C21: =21*38*1.03 -> 821.94 | D21: m² | E21: =假設與單價!$C$18+18 -> 99.544361 | F21: =C21*E21 -> 81819.492
A22: 3.3 | B22: 工業地坪 20 cm | C22: =21*38 -> 798 | D22: m² | E22: =假設與單價!$C$14 -> 62.22975 | F22: =C22*E22 -> 49659.341
A23: 3.4 | B23: 百葉窗、鐵捲門、鋼門（空壓機房通風） | C23: =1 -> 1 | D23: 式 | E23: 28000 | F23: =C23*E23 -> 28000
A24: 3.5 | B24: 內部隔間與裝修 | C24: =300 -> 300 | D24: m² | E24: =假設與單價!$C$16+2*假設與單價!$C$17 -> 59.514058 | F24: =C24*E24 -> 17854.217
B25: 小計 3. 外殼與裝修 | F25: =SUM(F20:F24) -> 236135.98
A27: 4 | B27: 機電（建築用；不含公用設備本體）
A28: 4.1 | B28: 電氣、照明、弱電 | C28: =1600 -> 1600 | D28: m² | E28: =假設與單價!$C$29+假設與單價!$C$30+假設與單價!$C$31 -> 77 | F28: =C28*E28 -> 123200 | G28: GFA 1,600 m²
A29: 4.2 | B29: 給排水、消防、通風 | C29: =1600 -> 1600 | D29: m² | E29: =假設與單價!$C$32+假設與單價!$C$33+假設與單價!$C$34 -> 63 | F29: =C29*E29 -> 100800
B30: 小計 4. 機電（建築用；不含公用設備本體） | F30: =SUM(F28:F29) -> 224000
A32: 5 | B32: 公用設備（土建整合部分；設備本體是否納入待 RFI 32）
A33: 5.1 | B33: 變電站土建 + MV 開關 + 變壓器 2 × 2,000 kVA | C33: =1 -> 1 | D33: 式 | E33: =假設與單價!$C$35 -> 380000 | F33: =C33*E33 -> 380000 | G33: RFI 28/29：負載表與位置待定；ANDE 線路另計
A34: 5.2 | B34: 緊急發電機 800 kVA | C34: =1 -> 1 | D34: 式 | E34: =假設與單價!$C$36 -> 165000 | F34: =C34*E34 -> 165000 | G34: RFI 29
A35: 5.3 | B35: 地下水池 100 m³ + 過濾水池 100 m³ + 廢水調勻池 200 m³（RC） | C35: =400 -> 400 | D35: m³ | E35: =假設與單價!$C$38 -> 420 | F35: =C35*E35 -> 168000 | G35: RFI 31：尺寸位置是否仍有效待確認
A36: 5.4 | B36: 深水井 150 m | C36: =1 -> 1 | D36: 口 | E36: =假設與單價!$C$39 -> 45000 | F36: =C36*E36 -> 45000
A37: 5.5 | B37: 空壓機 200HP × 7 kg/cm² + 200HP × 10 kg/cm² + 冷乾機（設備採購） | C37: =1 -> 1 | D37: 式 | E37: 210000 | F37: =C37*E37 -> 210000 | G37: RFI 32：由 S&W 或設備商；此為採購參考價，若 ACELON 自購請剔除
A38: 5.6 | B38: 冷卻水塔 CWS/CCWS 2 座 + 水泵 + 管路至管架 | C38: =1 -> 1 | D38: 式 | E38: 120000 | F38: =C38*E38 -> 120000
B39: 小計 5. 公用設備（土建整合部分；設備本體是否納入待 RFI 32） | F39: =SUM(F33:F38) -> 1088000
B41: 直接成本合計 (USD) | F41: =F10+F17+F25+F30+F39 -> 1857432

Sheet 基地工程
A1: 基地工程（第一次租賃範圍 158 × 106 m）— 直接成本明細
A2: 二／三期預定地與辦公室預定地未計（RFI 1）。
A4: 項次 | B4: 工程項目 | C4: 數量 | D4: 單位 | E4: 單價 (USD) | F4: 金額 (USD) | G4: 數量依據 / 說明
A5: 1 | B5: 整地與圍牆
A6: 1.1 | B6: 整地、表土剝除、粗整平（第一次租賃範圍 158 × 106 m） | C6: =158*106 -> 16748 | D6: m² | E6: 2.8 | F6: =C6*E6 -> 46894.4 | G6: 含 30 cm 表土剝除、填方 20 cm
A7: 1.2 | B7: 四周圍牆及樑柱（P0A30170） | C7: =2*(158+106) -> 528 | D7: m | E7: =假設與單價!$C$24 -> 135 | F7: =C7*E7 -> 71280 | G7: 周長 528 m
A8: 1.3 | B8: 大門 3 處（西側宿舍大門、工廠大門；南側 22 m 大門） | C8: =3 -> 3 | D8: 處 | E8: 14000 | F8: =C8*E8 -> 42000 | G8: 電動伸縮門
B9: 小計 1. 整地與圍牆 | F9: =SUM(F6:F8) -> 160174.4
A11: 2 | B11: 道路與鋪面
A12: 2.1 | B12: 廠區道路、卸貨區、停車場混凝土鋪面 18 cm | C12: =6500 -> 6500 | D12: m² | E12: =假設與單價!$C$23 -> 48 | F12: =C12*E12 -> 312000 | G12: 北側投料區 5 m 帶、東側 6 m 帶、南側 27.5 m 帶、西側通道
A13: 2.2 | B13: 投料區及粒包暫存區鋪面強化（30 cm RC） | C13: =32*4.5 -> 144 | D13: m² | E13: 65 | F13: =C13*E13 -> 9360 | G13: P0A30011 北側
A14: 2.3 | B14: 吊裝平台（RC，7 × 4 m） | C14: =1 -> 1 | D14: 式 | E14: 9000 | F14: =C14*E14 -> 9000 | G14: P0A30011 南端
B15: 小計 2. 道路與鋪面 | F15: =SUM(F12:F14) -> 330360
A17: 3 | B17: 守衛與附屬
A18: 3.1 | B18: 守衛室／會客室／餐廳（66 m², 1 層） | C18: =12*5.5 -> 66 | D18: m² | E18: 620 | F18: =C18*E18 -> 40920 | G18: 一般 RC＋磚造建物行情 USD 550–700/m²
A19: 3.2 | B19: 地磅 100 t（20 m）含基礎與儀表 | C19: =1 -> 1 | D19: 式 | E19: =假設與單價!$C$37 -> 62000 | F19: =C19*E19 -> 62000 | G19: ACELON 概算 NT$350,000
A20: 3.3 | B20: A/I 間（儀用空氣，5 × 5 m） | C20: =25 -> 25 | D20: m² | E20: 520 | F20: =C20*E20 -> 13000
B21: 小計 3. 守衛與附屬 | F21: =SUM(F18:F20) -> 115920
A23: 4 | B23: 公用管架與廠區管線
A24: 4.1 | B24: 公用管架（3 m 寬 × 5 m 高，61 m） | C24: =61 -> 61 | D24: m | E24: =假設與單價!$C$40 -> 900 | F24: =C24*E24 -> 54900 | G24: 公用區 → 原絲廠房管道間（G detail：18 種管線由業主自行處理，未計管材）
A25: 4.2 | B25: 廠區照明、雨水排水、汙水管線、綠化 | C25: =158*106 -> 16748 | D25: m² | E25: =假設與單價!$C$41 -> 6.5 | F25: =C25*E25 -> 108862 | G25: 園區主幹管已由 PTITP 提供（供水／汙水／雨水系統圖）
A26: 4.3 | B26: 園區給水／汙水／雨水接管費及 ANDE 23 kV 進線分攤 | C26: =1 -> 1 | D26: 式 | E26: 90000 | F26: =C26*E26 -> 90000 | G26: 依 PTITP 與 ANDE 協商（ptitp‑ande 案）；示意值
B27: 小計 4. 公用管架與廠區管線 | F27: =SUM(F24:F26) -> 253762
B29: 直接成本合計 (USD) | F29: =F9+F15+F21+F27 -> 860216.4

Sheet 風險與待確認
A1: 影響造價之未決事項（對應 Salum & Wenz RFI 與 9/4 回覆）
A2: 每項給出對總價的可能影響區間，供決策參考。
A4: RFI | B4: 事項 | C4: 目前估算假設 | D4: 可能影響 (USD) | E4: 說明
A5: 27 | B5: 地質鑽探尚未執行，基礎深度未定 | C5: 擴大基礎 30 座 3.5×3.5×0.9 m | D5: +80,000 ～ +350,000 | E5: Minga Guazú 紅土層若承載力不足需改樁基（30 支 × 12 m 鑽掘樁約 USD 300k）
A6: 22/25 | B6: 設備實際荷重與振動（擠壓機、捲繞機）未提供 | C6: 樓板 1,000 kg/m² + 圖面區域荷重 | D6: +50,000 ～ +250,000 | E6: 若需獨立隔振基礎或加厚樓板，混凝土與鋼筋量增加 5–10%
A7: 24 | B7: 4F 天車噸位與工作等級未定 | C7: 3 t 級軌道 2 × 73 m | D7: ±30,000 | E7: 5 t 級約 +USD 25k
A8: 23 | B8: 20 mm 鋼底板 3.8 × 8 m 是否為獨立設備基礎 | C8: 計入鋼板 4,770 kg | D8: −12,000 ～ +40,000
A9: 28/29 | B9: 變電站容量與位置、發電機容量 | C9: 2 × 2,000 kVA、800 kVA | D9: ±150,000 | E9: 兩份負載表功率不同；ANDE 23 kV 進線工程另計（PTITP 協商中）
A10: 30/32 | B10: 製程公用管網與空壓機房由誰設計／採購 | C10: 空壓機、冷乾機、冷卻水塔採購列於公用廠房表 | D10: −330,000（若 ACELON 自購） | E10: 剔除即減少
A11: 31 | B11: 水井、過濾池、廢水槽尺寸位置是否仍有效 | C11: 100/100/200 m³ RC | D11: ±60,000
A12: 1 | B12: 是否同時開發二、三期預定地 | C12: 未計 | D12: 另案 | E12: 二三期 94 × 106 m 整地約 USD 30k；廠房另估
A13: 19 | B13: 4合1 屋頂板是否含鎂板 | C13: 100 mm 岩棉三明治板 | D13: +15,000 ～ +40,000 | E13: 若改鎂質防火板複合，單價 +10–20%
A14: — | B14: 匯率與物價 | C14: ₲5,934.88/USD；CYPE 2024 單價 +10% | D14: ±5% | E14: 巴拉圭營建成本以 ₲ 計價且持續上漲（ABC 2026‑07）；鋼材受國際價格影響
A15: — | B15: 稅務結構 | C15: IVA 10% 全額計入 | D15: −10% | E15: Maquila（Ley 1064/97）或 Ley 60/90 投資獎勵可免進口設備關稅與 IVA；營建勞務 IVA 通常不可免，但可作進項扣抵
A16: — | B16: 工期與間接費 | C16: 未計工期延長之間接費 | D16: +2–4% | E16: 一次施工不分階段（9/4 回覆）；預計 14–18 個月

Sheet 資料來源
A1: 資料來源與參考
A3: BCP 參考匯率 2026‑09‑15：₲5,934.88/USD | B3: https://www.bcp.gov.py/webapps/web/cotizacion/referencial-fluctuante-interbancario
A4: costeo.com.py 巴拉圭建材價格：水泥 ₲59,000/袋、鋼筋 ₲7,390/kg、泵送混凝土 fck250 ₲900,000/m³、空心磚 ₲2,288 | B4: https://www.costeo.com.py/precios/materiales/
A5: CYPE Generador de precios Paraguay — 門式鋼架 ₲383,251/m²（32.8 kg/m²） | B5: https://paraguay.generadordeprecios.info/rehabilitacion/Estructuras/Acero/Montajes_industrializados/EAM010_Estructura_metalica_realizada_con_p.html
A6: CYPE Paraguay — RC 柱 ₲3,292,885/m³（混凝土 ₲874,041/m³、鋼筋 ₲6,249/kg、鋼模 ₲296,843/m²） | B6: https://paraguay.generadordeprecios.info/rehabilitacion/Estructuras/Hormigon_armado/Pilares/EHS010_Pilar_rectangular_o_cuadrado_de_hor.html
A7: CYPE Paraguay — 實心樓板 24 cm ₲583,257/m²（21 kg/m²，2024） | B7: https://paraguay.generadordeprecios.info/rehabilitacion/Estructuras/Hormigon_armado/Losas_macizas/Losa_maciza.html
A8: CYPE Paraguay — RC 基礎 ₲1,377,041/m³（50 kg/m³） | B8: https://paraguay.generadordeprecios.info/rehabilitacion/Fundaciones/Superficiales/Zapatas/Zapata_de_fundacion_de_hormigon_armado.html
A9: CYPE Paraguay — 三明治板屋面 100 mm ₲439,960/m² | B9: https://paraguay.generadordeprecios.info/obra_nueva/Cubiertas/QU_Componentes_de_cubiertas_incli/QUM_De_chapas_de_acero_y_paneles_s/QUM020_Cobertura_de_paneles_sandwich_aisla.html
A10: CYPE Paraguay — 磚隔間 7 cm ₲106,527/m² | B10: https://paraguay.generadordeprecios.info/rehabilitacion/Fachadas_y_particiones/FF_Mamposteria_no_estructural_de_/Hoja_para_revestir_en_particion/FFQ010_Hoja_de_particion_interior__de_mamp.html
A11: CYPE Paraguay — 工業地坪 20 cm ₲335,751/m² | B11: https://paraguay.generadordeprecios.info/rehabilitacion/Revestimientos_y_trasdosados/Pisos/RSI_Sistemas_de_pisos_industriales/RSI007_Piso_industrial_de_hormigon_tratado.html
A12: CYPE Paraguay — RC 擋土牆 ₲1,217,589/m³ | B12: https://paraguay.generadordeprecios.info/rehabilitacion/Urbanizacion_interior_de_la_parcela/Muros_de_contencion/Muros_de_contencion/Muro_de_contencion_de_hormigon_armado.html
A13: Mega Construcciones — 巴拉圭樓板行情 ₲650,000–2,000,000/m²（2026‑05） | B13: https://mega-construcciones.com/precio-de-losa-por-m2-en-paraguay/
A14: MTESS / ABC Color — 2026‑07 最低工資 ₲3,044,000/月；營建一級技工 ₲3,560,108/月 | B14: https://www.abc.com.py/economia/2026/07/08/reajuste-salarial-guia-completa-de-los-nuevos-montos-por-cada-sector-laboral/
... A18: ACELON 巴拉圭投資金額概算（廠房）WhatsApp 2026‑09‑10；Salum & Wenz IFC 2026‑07‑31；台灣方 9/4 回覆；P0A30011–P0A30170 圖說 | B18: 資料夾 acelon new factory py
